Exception on / [GET]
Traceback (most recent call last):
  File "/Users/kgorman/venv/lib/python2.7/site-packages/flask/app.py", line 1817, in wsgi_app
    response = self.full_dispatch_request()
  File "/Users/kgorman/venv/lib/python2.7/site-packages/flask/app.py", line 1477, in full_dispatch_request
    rv = self.handle_user_exception(e)
  File "/Users/kgorman/venv/lib/python2.7/site-packages/flask/app.py", line 1381, in handle_user_exception
    reraise(exc_type, exc_value, tb)
  File "/Users/kgorman/venv/lib/python2.7/site-packages/flask/app.py", line 1475, in full_dispatch_request
    rv = self.dispatch_request()
  File "/Users/kgorman/venv/lib/python2.7/site-packages/flask/app.py", line 1461, in dispatch_request
    return self.view_functions[rule.endpoint](**req.view_args)
  File "app.py", line 129, in dashboard
    ts_dow_labels=dow_graph[0],
NameError: global name 'dow_graph' is not defined
Exception on / [GET]
Traceback (most recent call last):
  File "/Users/kgorman/venv/lib/python2.7/site-packages/flask/app.py", line 1817, in wsgi_app
    response = self.full_dispatch_request()
  File "/Users/kgorman/venv/lib/python2.7/site-packages/flask/app.py", line 1477, in full_dispatch_request
    rv = self.handle_user_exception(e)
  File "/Users/kgorman/venv/lib/python2.7/site-packages/flask/app.py", line 1381, in handle_user_exception
    reraise(exc_type, exc_value, tb)
  File "/Users/kgorman/venv/lib/python2.7/site-packages/flask/app.py", line 1475, in full_dispatch_request
    rv = self.dispatch_request()
  File "/Users/kgorman/venv/lib/python2.7/site-packages/flask/app.py", line 1461, in dispatch_request
    return self.view_functions[rule.endpoint](**req.view_args)
  File "app.py", line 129, in dashboard
    ts_dow_labels=dow_graph[0],
NameError: global name 'dow_graph' is not defined
Exception on / [GET]
Traceback (most recent call last):
  File "/Users/kgorman/venv/lib/python2.7/site-packages/flask/app.py", line 1817, in wsgi_app
    response = self.full_dispatch_request()
  File "/Users/kgorman/venv/lib/python2.7/site-packages/flask/app.py", line 1477, in full_dispatch_request
    rv = self.handle_user_exception(e)
  File "/Users/kgorman/venv/lib/python2.7/site-packages/flask/app.py", line 1381, in handle_user_exception
    reraise(exc_type, exc_value, tb)
  File "/Users/kgorman/venv/lib/python2.7/site-packages/flask/app.py", line 1475, in full_dispatch_request
    rv = self.dispatch_request()
  File "/Users/kgorman/venv/lib/python2.7/site-packages/flask/app.py", line 1461, in dispatch_request
    return self.view_functions[rule.endpoint](**req.view_args)
  File "app.py", line 114, in dashboard
    dow_graph = get_speed_by_day(df)
  File "app.py", line 93, in get_speed_by_day
    print grouped.to_string()
  File "/Users/kgorman/venv/lib/python2.7/site-packages/pandas/core/groupby.py", line 556, in __getattr__
    return self._make_wrapper(attr)
  File "/Users/kgorman/venv/lib/python2.7/site-packages/pandas/core/groupby.py", line 573, in _make_wrapper
    raise AttributeError(msg)
AttributeError: Cannot access callable attribute 'to_string' of 'DataFrameGroupBy' objects, try using the 'apply' method
Exception on / [GET]
Traceback (most recent call last):
  File "/Users/kgorman/venv/lib/python2.7/site-packages/flask/app.py", line 1817, in wsgi_app
    response = self.full_dispatch_request()
  File "/Users/kgorman/venv/lib/python2.7/site-packages/flask/app.py", line 1477, in full_dispatch_request
    rv = self.handle_user_exception(e)
  File "/Users/kgorman/venv/lib/python2.7/site-packages/flask/app.py", line 1381, in handle_user_exception
    reraise(exc_type, exc_value, tb)
  File "/Users/kgorman/venv/lib/python2.7/site-packages/flask/app.py", line 1475, in full_dispatch_request
    rv = self.dispatch_request()
  File "/Users/kgorman/venv/lib/python2.7/site-packages/flask/app.py", line 1461, in dispatch_request
    return self.view_functions[rule.endpoint](**req.view_args)
  File "app.py", line 114, in dashboard
    dow_graph = get_speed_by_day(df)
  File "app.py", line 93, in get_speed_by_day
    grouped.to_csv(sys.stdout)
  File "/Users/kgorman/venv/lib/python2.7/site-packages/pandas/core/groupby.py", line 556, in __getattr__
    return self._make_wrapper(attr)
  File "/Users/kgorman/venv/lib/python2.7/site-packages/pandas/core/groupby.py", line 573, in _make_wrapper
    raise AttributeError(msg)
AttributeError: Cannot access callable attribute 'to_csv' of 'DataFrameGroupBy' objects, try using the 'apply' method
Exception on / [GET]
Traceback (most recent call last):
  File "/Users/kgorman/venv/lib/python2.7/site-packages/flask/app.py", line 1817, in wsgi_app
    response = self.full_dispatch_request()
  File "/Users/kgorman/venv/lib/python2.7/site-packages/flask/app.py", line 1477, in full_dispatch_request
    rv = self.handle_user_exception(e)
  File "/Users/kgorman/venv/lib/python2.7/site-packages/flask/app.py", line 1381, in handle_user_exception
    reraise(exc_type, exc_value, tb)
  File "/Users/kgorman/venv/lib/python2.7/site-packages/flask/app.py", line 1475, in full_dispatch_request
    rv = self.dispatch_request()
  File "/Users/kgorman/venv/lib/python2.7/site-packages/flask/app.py", line 1461, in dispatch_request
    return self.view_functions[rule.endpoint](**req.view_args)
  File "app.py", line 116, in dashboard
    dow_graph = get_speed_by_day(df)
  File "app.py", line 94, in get_speed_by_day
    groups = dict(list(gb))
NameError: global name 'gb' is not defined
Exception on / [GET]
Traceback (most recent call last):
  File "/Users/kgorman/venv/lib/python2.7/site-packages/flask/app.py", line 1817, in wsgi_app
    response = self.full_dispatch_request()
  File "/Users/kgorman/venv/lib/python2.7/site-packages/flask/app.py", line 1477, in full_dispatch_request
    rv = self.handle_user_exception(e)
  File "/Users/kgorman/venv/lib/python2.7/site-packages/flask/app.py", line 1381, in handle_user_exception
    reraise(exc_type, exc_value, tb)
  File "/Users/kgorman/venv/lib/python2.7/site-packages/flask/app.py", line 1475, in full_dispatch_request
    rv = self.dispatch_request()
  File "/Users/kgorman/venv/lib/python2.7/site-packages/flask/app.py", line 1461, in dispatch_request
    return self.view_functions[rule.endpoint](**req.view_args)
  File "app.py", line 115, in dashboard
    dow_graph = get_speed_by_day(df)
  File "app.py", line 94, in get_speed_by_day
    print grouped.get_group('day_of_week')
  File "/Users/kgorman/venv/lib/python2.7/site-packages/pandas/core/groupby.py", line 648, in get_group
    raise KeyError(name)
KeyError: 'day_of_week'
Exception on / [GET]
Traceback (most recent call last):
  File "/Users/kgorman/venv/lib/python2.7/site-packages/flask/app.py", line 1817, in wsgi_app
    response = self.full_dispatch_request()
  File "/Users/kgorman/venv/lib/python2.7/site-packages/flask/app.py", line 1477, in full_dispatch_request
    rv = self.handle_user_exception(e)
  File "/Users/kgorman/venv/lib/python2.7/site-packages/flask/app.py", line 1381, in handle_user_exception
    reraise(exc_type, exc_value, tb)
  File "/Users/kgorman/venv/lib/python2.7/site-packages/flask/app.py", line 1475, in full_dispatch_request
    rv = self.dispatch_request()
  File "/Users/kgorman/venv/lib/python2.7/site-packages/flask/app.py", line 1461, in dispatch_request
    return self.view_functions[rule.endpoint](**req.view_args)
  File "app.py", line 115, in dashboard
    dow_graph = get_speed_by_day(df)
  File "app.py", line 90, in get_speed_by_day
    print grouped.get_group('day_of_week')
  File "/Users/kgorman/venv/lib/python2.7/site-packages/pandas/core/groupby.py", line 648, in get_group
    raise KeyError(name)
KeyError: 'day_of_week'
Exception on / [GET]
Traceback (most recent call last):
  File "/Users/kgorman/venv/lib/python2.7/site-packages/flask/app.py", line 1817, in wsgi_app
    response = self.full_dispatch_request()
  File "/Users/kgorman/venv/lib/python2.7/site-packages/flask/app.py", line 1477, in full_dispatch_request
    rv = self.handle_user_exception(e)
  File "/Users/kgorman/venv/lib/python2.7/site-packages/flask/app.py", line 1381, in handle_user_exception
    reraise(exc_type, exc_value, tb)
  File "/Users/kgorman/venv/lib/python2.7/site-packages/flask/app.py", line 1475, in full_dispatch_request
    rv = self.dispatch_request()
  File "/Users/kgorman/venv/lib/python2.7/site-packages/flask/app.py", line 1461, in dispatch_request
    return self.view_functions[rule.endpoint](**req.view_args)
  File "app.py", line 138, in dashboard
    car_count_graph = car_count_by_hour(df)
  File "app.py", line 117, in car_count_by_hour
    keys = mean_speed.index.get_values()
NameError: global name 'mean_speed' is not defined
